Workbook

Sheet PAGOS
B1: MOTO | C1: MODELO | D1: MARCA | E1: PLACA | F1: MOVIL | G1: PRECIO | H1: INICIAL
A2: A21987G | B2: SBR | C2: 2026 | D2: BERA | E2: YIE71H | F2: MOVIL 08 | G2: 6000000 | H2: 800000
A4: COSTO -INICIAL | B4: INTERES | C4: COSTO NETO | D4: MESES | E4: MESUAL | F4: QUINCENAL | G4: SEMANAL | H4: DIARIO
A5: =G2-H2 -> 5200000 | B5: =2.3 -> 2.3 | C5: 13600000 | D5: 18 | E5: =C5/D5 -> 755555.56 | F5: =E5/2 -> 377777.78 | G5: =F5/2 -> 188888.89 | H5: =G5/6 -> 31481.481
A6: NOMBRES | B6: APELLIDO | C6: CEDULA | D6: NACIONALIDAD | E6: NUMERO | G6: Traspaso de propiedad | H6: DEUDA DE SEMANA
A7: JESUS ANDRES | B7: LOPEZ MORALES | C7: 30082499 | D7: VENEZOLANA | E7: 3169408429 | F7: SOAT | G7: FIRMA
H8: MESES
A9: SALDO ACTUAL PAGADO | C9: DEUDA A PAGAR | E9: DEUDA TOTAL. | G9: DEUDA ADQUIRIDA
A10: =I16+I26+I36+I46+I56+I66+I76+I86+I95 -> 3971000 | C10: =C5-A10 -> 9629000 | E10: =C10+G10 -> 9629000 | H10: =I23+I33+I43+I53+I63+I73+I83 -> 5
A12: RENTAL MOTORS S.A.S
A15: FECHA | B15: ABONO | C15: FECHA | D15: ABONO | E15: FECHA | F15: ABONO | G15: FECHA | H15: ABONO
A16: 46020 | C16: 46027 | E16: 46034 | G16: 46041 | I16: =B22+D22+F22+H22 -> 756000
A17: 46021 | C17: 46028 | E17: 46035 | G17: 46042
A18: 46022 | B18: 189000 | C18: 46029 | D18: 189000 | E18: 46036 | F18: 189000 | G18: 46043 | H18: 189000
A19: 46023 | C19: 46030 | E19: 46037 | G19: 46044
A20: 46024 | C20: 46031 | E20: 46038 | G20: 46045
A21: 46025 | C21: 46032 | E21: 46039 | G21: 46046
B22: =SUM(B16:B21) -> 189000 | D22: =SUM(D16:D21) -> 189000 | F22: =SUM(F16:F21) -> 189000 | H22: =SUM(H16:H21) -> 189000 | I22: 1
A23: REF. | C23: REF. | E23: REF. | G23: REF. | I23: 1
A25: FECHA | B25: ABONO | C25: FECHA | D25: ABONO | E25: FECHA | F25: ABONO | G25: FECHA | H25: ABONO
A26: 46048 | C26: 46055 | D26: 189000 | E26: 46062 | F26: 189000 | G26: 46069 | H26: 189000 | I26: =B32+D32+F32+H32 -> 756000
A27: 46049 | C27: 46056 | E27: 46063 | G27: 46070
A28: 46050 | B28: 189000 | C28: 46057 | E28: 46064 | G28: 46071
A29: 46051 | C29: 46058 | E29: 46065 | G29: 46072
A30: 46052 | C30: 46059 | E30: 46066 | G30: 46073
A31: 46053 | C31: 46060 | E31: 46067 | G31: 46074
B32: =SUM(B26:B31) -> 189000 | D32: =SUM(D26:D31) -> 189000 | F32: =SUM(F26:F31) -> 189000 | H32: =SUM(H26:H31) -> 189000 | I32: 2
A33: REF. | C33: REF. | D33: M02140271 | E33: REF. | F33: M00156218 | G33: REF. | H33: M03166817 | I33: 1
A35: FECHA | B35: ABONO | C35: FECHA | D35: ABONO | E35: FECHA | F35: ABONO | G35: FECHA | H35: ABONO
A36: 46076 | B36: 189000 | C36: 46083 | D36: 189000 | E36: 46090 | F36: 189000 | G36: 46097 | H36: 189000 | I36: =B42+D42+F42+H42 -> 756000
A37: 46077 | C37: 46084 | E37: 46091 | G37: 46098
A38: 46078 | C38: 46085 | E38: 46092 | G38: 46099
A39: 46079 | C39: 46086 | E39: 46093 | G39: 46100
A40: 46080 | C40: 46087 | E40: 46094 | G40: 46101
A41: 46081 | C41: 46088 | E41: 46095 | G41: 46102
B42: =SUM(B36:B41) -> 189000 | D42: =SUM(D36:D41) -> 189000 | F42: =SUM(F36:F41) -> 189000 | H42: =SUM(H36:H41) -> 189000 | I42: 3
A43: REF. | C43: REF. | E43: REF. | G43: REF. | I43: 1
A45: FECHA | B45: ABONO | C45: FECHA | D45: ABONO | E45: FECHA | F45: ABONO | G45: FECHA | H45: ABONO
A46: 46104 | B46: 189000 | C46: 46111 | D46: 189000 | E46: 46118 | F46: 189000 | G46: 46125 | H46: 189000 | I46: =B52+D52+F52+H52 -> 756000
A47: 46105 | C47: 46112 | E47: 46119 | G47: 46126
...

Sheet Hoja 2
A1: RENTAL MOTORS S.A.S
A3: SOLO PAGOS POR BANCOLOMBIA | C3: =PAGOS!A7 -> JESUS ANDRES
A4: FECHA DEL PRESTAMOS | B4: =PAGOS!A16 -> 46020
A5: COSTO DEL VEICULO | B5: =PAGOS!G2 -> 6000000 | C5: MOVIL 08
A6: INICIAL DEL VEICULO | B6: =PAGOS!H2 -> 800000
A7: PRESTAMO | B7: =PAGOS!A5 -> 5200000
A8: TASA DE INTERES ( 2,38) | B8: =PAGOS!C5 -> 13600000
A9: COSTO NETO DE LA MOTO | B9: =PAGOS!C5 -> 13600000
A10: SOAT | B10: 380000
A12: Traspaso de propiedad | B12: 280000
A13: MENSUALIDA GPS | B13: 25000
A14: TOTAL APAGAR GPS
A15: MESES A PAGAR | B15: 26
A16: COSTO NETO DE LA MOTO CON LOS TRAMITES Y SERVICIO
A17: SALDO PAGADO | B17: SALDO PENDIENTE | C17: DEUDA ADQUIRIDA | D17: MESES ADQUIRIDO | E17: MESES PAGADO
A18: =PAGOS!A10 -> 3971000 | B18: =PAGOS!C10 -> 9629000 | C18: =PAGOS!E10 -> 9629000
