Workbook

Sheet PAGOS
A1: CODIGO | B1: MOTO | C1: MODELO | E1: PLACA | F1: MOVIL | G1: PRECIO | H1: INICIAL
A2: A219782G | B2: BOXER | C2: 2026 | D2: BAJA | E2: RMC-63H | F2: 03 | G2: 6800000 | H2: 1050000
A4: COSTO -INICIAL | B4: INTERES | C4: COSTO NETO | D4: MESES | E4: MESUAL | F4: QUINCENAL | G4: SEMANAL | H4: DIARIO
A5: =G2-H2 -> 5750000 | B5: =A5*158% -> 9085000 | C5: =A5+B5 -> 14835000 | D5: 18 | E5: =C5/D5 -> 824166.67 | F5: =E5/2 -> 412083.33 | G5: =E5/4 -> 206041.67 | H5: =G5/6 -> 34340.278
A6: NOMBRES | B6: APELLIDO | C6: CEDULA | D6: NACIONALIDAD | E6: NUMERO | G6: Traspaso de propiedad | H6: DEUDA DE SEMANA
A7: DENYS JOSE | B7: GALVE QUINTERO | C7: 14747830 | D7: VENEZUELA | E7: 3017150430 | F7: SOAT | G7: FIRMA
H8: MESES
A9: SALDO ACTUAL PAGADO | C9: DEUDA A PAGAR | E9: DEUDA TOTAL. | G9: DEUDA ADQUIRIDA
A10: =I16+I26+I36+I46+I56+I66+I76+I86+I96+I106 -> 8078000 | C10: =C5-A10 -> 6757000 | E10: =C10+G10+H7 -> 6757000 | G10: =G8+F8 -> 0 | H10: =I23+I33+I43+I53+I63+I73+I83+I93+I103+I113 -> 9
A12: RENTAL MOTORS S.A.S
A15: FECHA | B15: ABONO | C15: FECHA | D15: ABONO | E15: FECHA | F15: ABONO | G15: FECHA | H15: ABONO
A16: 45894 | B16: 207000 | C16: 45901 | D16: 207000 | E16: 45908 | F16: 212000 | G16: 45915 | H16: 207000 | I16: =B22+D22+F22+H22 -> 833000
A17: 45895 | C17: 45902 | E17: 45909 | G17: 45916
A18: 45896 | C18: 45903 | E18: 45910 | G18: 45917
A19: 45897 | C19: 45904 | E19: 45911 | G19: 45918
A20: 45898 | C20: 45905 | E20: 45912 | G20: 45919
A21: 45899 | C21: 45906 | E21: 45913 | G21: 45920
B22: =SUM(B16:B21) -> 207000 | D22: =SUM(D16:D21) -> 207000 | F22: =SUM(F16:F21) -> 212000 | H22: =SUM(H16:H21) -> 207000 | I22: 1
A23: REF. | C23: REF. | E23: REF. | G23: REF. | I23: 1
A25: FECHA | B25: ABONO | C25: FECHA | D25: ABONO | E25: FECHA | F25: ABONO | G25: FECHA | H25: ABONO
A26: 45922 | B26: 207000 | C26: 45929 | D26: 207000 | E26: 45936 | F26: 207000 | G26: 45943 | H26: 207000 | I26: =B32+D32+F32+H32 -> 828000
A27: 45923 | C27: 45930 | E27: 45937 | G27: 45944
A28: 45924 | C28: 45931 | E28: 45938 | G28: 45945
A29: 45925 | C29: 45932 | E29: 45939 | G29: 45946
A30: 45926 | C30: 45933 | E30: 45940 | G30: 45947
A31: 45927 | C31: 45934 | E31: 45941 | G31: 45948
B32: =SUM(B26:B31) -> 207000 | D32: =SUM(D26:D31) -> 207000 | F32: =SUM(F26:F31) -> 207000 | H32: =SUM(H26:H31) -> 207000 | I32: 2
A33: REF. | C33: REF. | E33: REF. | G33: REF. | I33: 1
A35: FECHA | B35: ABONO | C35: FECHA | D35: ABONO | E35: FECHA | F35: ABONO | G35: FECHA | H35: ABONO
A36: 45950 | B36: 207000 | C36: 45957 | D36: 207000 | E36: 45964 | F36: 207000 | G36: 45971 | H36: 207000 | I36: =B42+D42+F42+H42 -> 828000
A37: 45951 | C37: 45958 | E37: 45965 | G37: 45972
A38: 45952 | C38: 45959 | E38: 45966 | G38: 45973
A39: 45953 | C39: 45960 | E39: 45967 | G39: 45974
A40: 45954 | C40: 45961 | E40: 45968 | G40: 45975
A41: 45955 | C41: 45962 | E41: 45969 | G41: 45976
B42: =SUM(B36:B41) -> 207000 | D42: =SUM(D36:D41) -> 207000 | F42: =SUM(F36:F41) -> 207000 | H42: =SUM(H36:H41) -> 207000 | I42: 3
A43: REF. | C43: REF. | E43: REF. | G43: REF. | I43: 1
A45: FECHA | B45: ABONO | C45: FECHA | D45: ABONO | E45: FECHA | F45: ABONO | G45: FECHA | H45: ABONO
A46: 45978 | B46: 207000 | C46: 45985 | D46: 207000 | E46: 45992 | F46: 207000 | G46: 45999 | H46: 207000 | I46: =B52+D52+F52+H52 -> 828000
A47: 45979 | C47: 45986 | E47: 45993 | G47: 46000
...

Sheet SEMANAL
A1: RENTAL MOTORS S.A.S
A3: SOLO PAGOS POR BANCOLOMBIA | C3: =PAGOS!A7 -> DENYS JOSE
A4: FECHA DEL PRESTAMOS | B4: =PAGOS!A16 -> 45894
A5: COSTO DEL VEICULO | B5: =PAGOS!G2 -> 6800000 | C5: MOVIL 03
A6: INICIAL DEL VEICULO | B6: =PAGOS!H2 -> 1050000
A7: PRESTAMO | B7: =B5-B6 -> 5750000
A8: TASA DE INTERES ( 1,9%) | B8: =PAGOS!C5 -> 14835000
A9: COSTO NETO DE LA MOTO
A10: SOAT | B10: =PAGOS!F8 | C10: =PAGOS!G4 -> SEMANAL
A12: Traspaso de propiedad | B12: =PAGOS!G8
A13: MENSUALIDA GPS | C13: =PAGOS!G5 -> 206041.67
A14: TOTAL APAGAR GPS
A15: MESES A PAGAR | B15: 26
A16: COSTO NETO DE LA MOTO CON LOS TRAMITES Y SERVICIO | B16: =B9+B10+B11+B12+B14 -> 0
A17: SALDO PAGADO | B17: SALDO PENDIENTE | C17: DEUDA ADQUIRIDA | D17: MESES ADQUIRIDO | E17: MESES PAGADO
A18: =PAGOS!A10 -> 8078000 | B18: =PAGOS!C10 -> 6757000 | C18: =PAGOS!G10 -> 0
