Workbook

Sheet PAGOS
A1: CODIGO | B1: MOTO | C1: MODELO | D1: MARCA | E1: PLACA | F1: MOVIL | G1: PRECIO | H1: INICIAL
A2: A2175 | B2: PULSAR N160 | C2: 2026 | D2: BAJAJ | E2: RLI49H | F2: 31 | G2: 11000000 | H2: 1900000
A4: COSTO -INICIAL | B4: INTERES | C4: COSTO NETO | D4: MESES | E4: MESUAL | F4: QUINCENAL | G4: SEMANAL | H4: DIARIO
A5: =G2 -> 11000000 | B5: =A5*1.3905 -> 15295500 | C5: =B5+A5 -> 26295500 | D5: 26 | E5: =C5/D5 -> 1011365.4 | F5: =E5/2 -> 505682.69 | G5: =F5/2 -> 252841.35 | H5: =G5/6 -> 42140.224
A6: NOMBRES | B6: APELLIDO | C6: CEDULA | D6: NACIONALIDAD | E6: NUMERO | F6: SOAT | G6: Traspaso de propiedad | H6: PRESTAMO.
A7: KEIFER ANTONIO | B7: GONZALEZ GARCIA | C7: 1047520588 | D7: COLOMBIANO | E7: 3226603949 | F7: ACTIVO | G7: ACTIVO | H7: 0
A9: SALDO ACTUAL PAGADO | C9: DEUDA A PAGAR | E9: DEUDA TOTAL | G9: DEUDA ADQUIRIDA | H9: MESES
A10: =I14+I24+I34+I44+I54+I64+I74+I84+I94+I104+I114+I124 -> 11849000 | C10: =C5-A10 -> 14446500 | E10: =C10+G10 -> 14446500
H11: =I21+I31+I41+I51+I61+I71+I81+I91+I101+I111+I121+I131 -> 11
A12: RENTAL MOTORS S.A.S
A13: FECHA | B13: ABONO | C13: FECHA | D13: ABONO | E13: FECHA | F13: ABONO | G13: FECHA | H13: ABONO
A14: 45845 | B14: 253000 | C14: 45852 | D14: 253000 | E14: 45859 | F14: 253000 | G14: 45866 | H14: 253000 | I14: =B20+D20+F20+H20 -> 1012000
A15: 45846 | C15: 45853 | E15: 45860 | G15: 45867
A16: 45847 | C16: 45854 | E16: 45861 | G16: 45868
A17: 45848 | C17: 45855 | E17: 45862 | G17: 45869
A18: 45849 | C18: 45856 | E18: 45863 | G18: 45870
A19: 45850 | C19: 45857 | E19: 45864 | G19: 45871
B20: =SUM(B14:B19) -> 253000 | D20: =SUM(D14:D19) -> 253000 | F20: =SUM(F14:F19) -> 253000 | H20: =SUM(H14:H19) -> 253000 | I20: 1
A21: REF. | B21: M12104683 | C21: REF. | D21: M17963077 | E21: REF. | F21: M3646386 | G21: REF. | H21: M1590008 | I21: 1
A23: FECHA | B23: ABONO | C23: FECHA | D23: ABONO | E23: FECHA | F23: ABONO | G23: FECHA | H23: ABONO
A24: 45873 | B24: 253000 | C24: 45880 | D24: 253000 | E24: 45887 | F24: 253000 | G24: 45894 | H24: 253000 | I24: =B30+D30+F30+H30 -> 1012000
A25: 45874 | C25: 45881 | E25: 45888 | G25: 45895
A26: 45875 | C26: 45882 | E26: 45889 | G26: 45896
A27: 45876 | C27: 45883 | E27: 45890 | G27: 45897
A28: 45877 | C28: 45884 | E28: 45891 | G28: 45898
A29: 45878 | C29: 45885 | E29: 45892 | G29: 45899
B30: =SUM(B24:B29) -> 253000 | D30: =SUM(D24:D29) -> 253000 | F30: =SUM(F24:F29) -> 253000 | H30: =SUM(H24:H29) -> 253000 | I30: 2
A31: REF. | C31: REF. | E31: REF. | F31: M11235522 | G31: REF. | H31: M18095203 | I31: 1
A33: FECHA | B33: ABONO | C33: FECHA | D33: ABONO | E33: FECHA | F33: ABONO | G33: FECHA | H33: ABONO
A34: 45901 | B34: 253000 | C34: 45908 | D34: 253000 | E34: 45915 | F34: 253000 | G34: 45922 | H34: 253000 | I34: =B40+D40+F40+H40 -> 1012000
A35: 45902 | C35: 45909 | E35: 45916 | G35: 45923
A36: 45903 | C36: 45910 | E36: 45917 | G36: 45924
A37: 45904 | C37: 45911 | E37: 45918 | G37: 45925
A38: 45905 | C38: 45912 | E38: 45919 | G38: 45926
A39: 45906 | C39: 45913 | E39: 45920 | G39: 45927
B40: =SUM(B34:B39) -> 253000 | D40: =SUM(D34:D39) -> 253000 | F40: =SUM(F34:F39) -> 253000 | H40: =SUM(H34:H39) -> 253000 | I40: 3
A41: REF. | B41: M15069032 | C41: REF. | D41: M12186578 | E41: REF. | F41: M23693958 | G41: REF. | H41: M22386553 | I41: 1
A43: FECHA | B43: ABONO | C43: FECHA | D43: ABONO | E43: FECHA | F43: ABONO | G43: FECHA | H43: ABONO
A44: 45927 | B44: 253000 | C44: 45929 | D44: 253000 | E44: 45936 | F44: 253000 | G44: 45943 | H44: 253000 | I44: =B50+D50+F50+H50 -> 1012000
A45: 45928 | C45: 45930 | E45: 45937 | G45: 45944
...

Sheet MOVIL 31
A1: RENTAL MOTORS S.A.S Nit. 901843215-2
A5: FOTO | C5: =DATA!B4 -> NOMBRE Y APELLIDO | D5: =DATA!C4 -> CEDULA | E5: =DATA!D4 -> N/CONTACTO
C6: =DATA!B5 -> KEIFER ANTONIO GONZALEZ GARCIA | D6: =DATA!C5 -> 1047520588 | E6: =DATA!D5 -> 3116358471
C7: =DATA!A5 -> MOVIL 31
C9: =PAGOS!A9 -> SALDO ACTUAL PAGADO | D9: =PAGOS!C9 -> DEUDA A PAGAR
C12: =PAGOS!A10 -> 11849000 | D12: =PAGOS!C10 -> 14446500
A13: CUOTAS TOTALES | C13: =PAGOS!H9 -> MESES | D13: CUOTAS RESTANTES
A14: =PAGOS!D5 -> 26 | C14: =PAGOS!H11 -> 11 | D14: =PAGOS!D5-PAGOS!H11 -> 15
A15: CODIGO | B15: MOTO | C15: MODELO | D15: MARCA | E15: PLACA
A16: A2175 | B16: PULSAR N160 | C16: 2026 | D16: BAJAJ | E16: RLI49H
C17: SOAT | D17: Traspaso de propiedad | E17: PRESTAMO.
C18: ACTIVO | D18: ACTIVO | E18: 0

Sheet DATA
A1: RENTAL MOTORS S.A.S Nit. 901843215-2
A4: MOVIL | B4: NOMBRE Y APELLIDO | C4: CEDULA | D4: N/CONTACTO | E4: CORREO ELECTRONICO | F4: FECHA DE INICIO | G4: DIRECCION | H4: CIUDAD | I4: BARRIO
A5: MOVIL 31 | B5: KEIFER ANTONIO GONZALEZ GARCIA | C5: 1047520588 | D5: 3116358471 | F5: =PAGOS!A14 -> 45845
B8: DATOS PERSONALES
B9: NOMBRE Y APELLIDO | C9: PARESTESCO | D9: CEDULA | E9: N/CONTACTO
B10: YAMIL CASSINI | C10: PERSONAL | D10: 1043296445 | E10: 3205594282
B11: ERIC TRMPIZ | C11: PERSONAL | D11: 6814746 | E11: 3234961211
B13: NOMBRE Y APELLIDO | C13: PARESTESCO | D13: CEDULA | E13: N/CONTACTO
B14: EDIXON GONZALEZ | C14: FAMILIAR | D14: 7823548 | E14: 3116358471
B15: GLORIA GARCIA | C15: FAMILIAR | D15: 45452518 | E15: 3116358471

Sheet COTIZACION
A1: RENTAL MOTORS S.A.S Nit. 901843215-2
A4: PLAN A
A5: PRECIO | B5: INICIAL | C5: COSTO -INICIAL | D5: INTERES | E5: COSTO NETO | F5: MESES | G5: MESUAL | H5: QUINCENAL | I5: SEMANAL | J5: DIARIO
A6: 11000000 | B6: 1900000 | C6: =A6-B6 -> 9100000 | D6: =C6*1.45 -> 13195000 | E6: =D6+C6+B11+C11+D11 -> 23125000 | F6: 18 | G6: =E6/F6 -> 1284722.2 | H6: =G6/2 -> 642361.11 | I6: =H6/2 -> 321180.56 | J6: =I6/6 -> 53530.093
A7: 11000000 | B7: 1900000 | C7: =A7-B7 -> 9100000 | D7: =C7*1.78 -> 16198000 | E7: =D7+C7+B12+C12 -> 26328000 | F7: 26 | G7: =E7/F7 -> 1012615.4 | H7: =G7/2 -> 506307.69 | I7: =H7/2 -> 253153.85 | J7: =I7/6 -> 42192.308
A8: 11000000 | B8: 1900000 | C8: =A8-B8 -> 9100000 | D8: =C8*1.98 -> 18018000 | E8: =D8+C8+B13+C13 -> 28398000 | F8: 36 | G8: =E8/F8 -> 788833.33 | H8: =G8/2 -> 394416.67 | I8: =H8/2 -> 197208.33 | J8: =I8/6 -> 32868.056
A10: GPS MENSUAL | B10: GPS | C10: Papeles & Gps | D10: SOAT | E10: TOTAL
B11: =F6*A12 -> 450000 | C11: 380000
A12: 25000 | B12: =F7*A12 -> 650000 | C12: 380000
B13: =F8*A12 -> 900000 | C13: 380000
