Workbook

Sheet PAGOS
A1: CODIGO | B1: MOTO | C1: MODELO | D1: MARCA | E1: PLACA | F1: MOVIL | G1: PRECIO | H1: INICIAL
A2: A219782G | B2: BERA | C2: 2025 | D2: SBR150 | E2: UGO53H | F2: 39 | G2: 5800000 | H2: 800000
A4: COSTO -INICIAL | B4: INTERES | C4: COSTO NETO | D4: MESES | E4: MESUAL | F4: QUINCENAL | G4: SEMANAL | H4: DIARIO
A5: =G2 -> 5800000 | B5: =A5*1.3 -> 7540000 | C5: =B5+A5 -> 13340000 | D5: 18 | E5: =C5/D5 -> 741111.11 | F5: =E5/2 -> 370555.56 | G5: =F5/2 -> 185277.78 | H5: =G5/6 -> 30879.63
A6: NOMBRES | B6: APELLIDO | C6: CEDULA | D6: NACIONALIDAD | E6: NUMERO | F6: SOAT | G6: Traspaso de propiedad | H6: PRESTAMO.
A7: ERIK FERNANDO | B7: SALAZAR | C7: PPT -5383521 | D7: VENEZOLANO | E7: 3014696455 | F7: ACTIVO | G7: ACTIVO | H7: 0
F8: 380000 | G8: 280000
A9: SALDO ACTUAL PAGADO | C9: DEUDA A PAGAR | E9: DEUDA TOTAL | G9: D. ADQUIRIDA | H9: MESES
A10: =I15+I25+I35+I45+I55+I65+I75+I85 -> 4978225 | C10: =C5-A10 -> 8361775 | E10: =C10+G10 -> 8361775
H11: =I22+I32+I42+I52+I62+I72+I82+I92 -> 7
A12: RENTAL MOTORS S.A.S
A14: FECHA | B14: ABONO | C14: FECHA | D14: ABONO | E14: FECHA | F14: ABONO | G14: FECHA | H14: ABONO
A15: 45971 | B15: 154225 | C15: 45978 | D15: 185000 | E15: 45985 | F15: 185000 | G15: 45992 | H15: 110000 | I15: =B21+D21+F21+H21 -> 634225
A16: 45972 | C16: 45979 | E16: 45986 | G16: 45993
A17: 45973 | C17: 45980 | E17: 45987 | G17: 45994
A18: 45974 | C18: 45981 | E18: 45988 | G18: 45995
A19: 45975 | C19: 45982 | E19: 45989 | G19: 45996
A20: 45976 | C20: 45983 | E20: 45990 | G20: 45997
B21: =SUM(B15:B20) -> 154225 | D21: =SUM(D15:D20) -> 185000 | F21: =SUM(F15:F20) -> 185000 | H21: =SUM(H15:H20) -> 110000 | I21: 1
A22: REF. | B22: M02629925 | C22: REF. | D22: M16437684 | E22: REF. | F22: M05720987 | G22: REF. | I22: 1
A24: FECHA | B24: ABONO | C24: FECHA | D24: ABONO | E24: FECHA | F24: ABONO | G24: FECHA | H24: ABONO
A25: 45999 | B25: 153000 | C25: 46006 | D25: 185000 | E25: 46013 | F25: 185000 | G25: 46020 | H25: 120000 | I25: =B31+D31+F31+H31 -> 675000
A26: 46000 | B26: 32000 | C26: 46007 | E26: 46014 | G26: 46021
A27: 46001 | C27: 46008 | E27: 46015 | G27: 46022
A28: 46002 | C28: 46009 | E28: 46016 | G28: 46023
A29: 46003 | C29: 46010 | E29: 46017 | G29: 46024
A30: 46004 | C30: 46011 | E30: 46018 | G30: 46025
B31: =SUM(B25:B30) -> 185000 | D31: =SUM(D25:D30) -> 185000 | F31: =SUM(F25:F30) -> 185000 | H31: =SUM(H25:H30) -> 120000 | I31: 2
A32: REF. | B32: 35618 | C32: REF. | D32: M1061742 | E32: REF. | F32: M12039071 | G32: REF. | H32: M18963662 | I32: 1
A34: FECHA | B34: ABONO | C34: FECHA | D34: ABONO | E34: FECHA | F34: ABONO | G34: FECHA | H34: ABONO
A35: 46027 | B35: 170000 | C35: 46034 | D35: 185000 | E35: 46041 | F35: 185000 | G35: 46048 | H35: 185000 | I35: =B41+D41+F41+H41 -> 740000
A36: 46028 | B36: 15000 | C36: 46035 | E36: 46042 | G36: 46049
A37: 46029 | C37: 46036 | E37: 46043 | G37: 46050
A38: 46030 | C38: 46037 | E38: 46044 | G38: 46051
A39: 46031 | C39: 46038 | E39: 46045 | G39: 46052
A40: 46032 | C40: 46039 | E40: 46046 | G40: 46053
B41: =SUM(B35:B40) -> 185000 | D41: =SUM(D35:D40) -> 185000 | F41: =SUM(F35:F40) -> 185000 | H41: =SUM(H35:H40) -> 185000 | I41: 3
A42: REF. | B42: M12690057 | C42: REF. | D42: M13930326 | E42: REF. | G42: REF. | I42: 1
A44: FECHA | B44: ABONO | C44: FECHA | D44: ABONO | E44: FECHA | F44: ABONO | G44: FECHA | H44: ABONO
A45: 46055 | B45: 185000 | C45: 46062 | D45: 185000 | E45: 46069 | F45: 185000 | G45: 46076 | H45: 185000 | I45: =B51+D51+F51+H51 -> 740000
...

Sheet Hoja 2
A1: RENTAL MOTORS S.A.S Nit. 901843215-2
A5: FOTO | C5: =DATA!B4 -> #REF! | D5: =DATA!C4 -> #REF! | E5: =DATA!D4 -> #REF!
C6: =DATA!B5 -> #REF! | D6: =DATA!C5 -> #REF! | E6: =DATA!D5 -> #REF!
C7: =DATA!A5 -> #REF!
C9: =PAGOS!A9 -> #REF! | D9: =PAGOS!C9 -> #REF!
C12: =PAGOS!A10 -> #REF! | D12: =PAGOS!C10 -> #REF!
A13: CUOTAS TOTALES | C13: =PAGOS!H9 -> #REF! | D13: CUOTAS RESTANTES
A14: =PAGOS!D5 -> #REF! | C14: =PAGOS!H11 -> #REF! | D14: =PAGOS!D5-PAGOS!H11 -> #REF!
A15: CODIGO | B15: MOTO | C15: MODELO | D15: MARCA | E15: PLACA
A16: A2175 | B16: PULSAR N160 | C16: 2026 | D16: BAJAJ | E16: RLI49H
C17: SOAT | D17: Traspaso de propiedad | E17: PRESTAMO.
C18: ACTIVO | D18: ACTIVO | E18: 0
