Workbook

Sheet PAGOS
A1: CODIGO | B1: MOTO | C1: MODELO | D1: MARCA | E1: PLACA | F1: MOVIL | G1: PRECIO | H1: INICIAL | I1: 12699500
A2: A2175 | B2: SBR | C2: 2024 | D2: BERA | E2: NDE68H- | F2: 32 | G2: 5600000 | H2: 450000
A4: COSTO -INICIAL | B4: INTERES | C4: COSTO NETO | D4: MESES | E4: MESUAL | F4: QUINCENAL | G4: SEMANAL | H4: DIARIO
A5: =G2-H2 -> 5150000 | B5: =A5*1.41 -> 7261500 | C5: =B5+A5 -> 12411500 | D5: 18 | E5: 714000 | F5: =E5/2 -> 357000 | G5: =F5/2 -> 178500 | H5: =G5/6 -> 29750
A6: NOMBRES | B6: APELLIDO | C6: P.P.T | D6: NACIONALIDAD | E6: NUMERO | F6: SOAT | G6: Traspaso de propiedad | H6: PRESTAMO.
A7: JULIO CESAR | B7: HERNANDEZ | C7: 5882282 | D7: VENEZOLANO | F7: ACTIVO | G7: ACTIVO | H7: 0
A9: SALDO ACTUAL PAGADO | C9: DEUDA A PAGAR | E9: DEUDA TOTAL | G9: D. ADQUIRIDA | H9: CUOTA MENSUAL #
A10: =I15+I25+I35+I45+I55+I65+I75+I85+I95+I105+I115+I125+I135+I145+I155 -> 10530000 | C10: =C5-A10 -> 1881500 | E10: =C10+G10 -> 1881500
H11: =I22+I32+I42+I52+I62+I72+I82+I92+I102+I112+I122+I132+I142+I152+I162 -> 14
A12: RENTAL MOTORS S.A.S
A14: FECHA | B14: ABONO | C14: FECHA | D14: ABONO | E14: FECHA | F14: ABONO | G14: FECHA | H14: ABONO
C15: 45761 | E15: 45768 | G15: 45775 | I15: =B21+D21+F21+H21 -> 630000
C16: 45762 | E16: 45769 | G16: 45776
C17: 45763 | D17: 180000 | E17: 45770 | F17: 180000 | G17: 45777 | H17: 180000
C18: 45764 | E18: 45771 | G18: 45778
A19: 45758 | B19: 90000 | C19: 45765 | E19: 45772 | G19: 45779
A20: 45759 | C20: 45766 | E20: 45773 | G20: 45780
B21: =SUM(B15:B20) -> 90000 | D21: =SUM(D15:D20) -> 180000 | F21: =SUM(F15:F20) -> 180000 | H21: =SUM(H15:H20) -> 180000 | I21: 1
A22: REF. | B22: EFECTIIVO | C22: REF. | D22: M5031425 | E22: REF. | F22: M5922059 | G22: REF. | H22: M10904490 | I22: 1
A24: FECHA | B24: ABONO | C24: FECHA | D24: ABONO | E24: FECHA | F24: ABONO | G24: FECHA | H24: ABONO
A25: 45782 | C25: 45789 | E25: 45796 | G25: 45803 | I25: =B31+D31+F31+H31 -> 720000
A26: 45783 | C26: 45790 | E26: 45797 | G26: 45804
A27: 45784 | B27: 180000 | C27: 45791 | D27: 180000 | E27: 45798 | F27: 180000 | G27: 45805 | H27: 180000
A28: 45785 | C28: 45792 | E28: 45799 | G28: 45806
A29: 45786 | C29: 45793 | E29: 45800 | G29: 45807
A30: 45787 | C30: 45794 | E30: 45801 | G30: 45808
B31: =SUM(B25:B30) -> 180000 | D31: =SUM(D25:D30) -> 180000 | F31: =SUM(F25:F30) -> 180000 | H31: =SUM(H25:H30) -> 180000 | I31: 2
A32: REF. | B32: M10288520 | C32: REF. | D32: M14985720 | E32: REF. | F32: EFECTIVO | G32: REF. | H32: M4937797 | I32: 1
A34: FECHA | B34: ABONO | C34: FECHA | D34: ABONO | E34: FECHA | F34: ABONO | G34: FECHA | H34: ABONO
A35: 45810 | C35: 45817 | E35: 45824 | G35: 45831 | I35: =B41+D41+F41+H41 -> 720000
A36: 45811 | C36: 45818 | E36: 45825 | G36: 45832
A37: 45812 | C37: 45819 | E37: 45826 | G37: 45833
A38: 45813 | B38: 180000 | C38: 45820 | D38: 180000 | E38: 45827 | F38: 180000 | G38: 45834 | H38: 180000
A39: 45814 | C39: 45821 | E39: 45828 | G39: 45835
A40: 45815 | C40: 45822 | E40: 45829 | G40: 45836
B41: =SUM(B35:B40) -> 180000 | D41: =SUM(D35:D40) -> 180000 | F41: =SUM(F35:F40) -> 180000 | H41: =SUM(H35:H40) -> 180000 | I41: 3
A42: REF. | B42: M10720724 | C42: REF. | D42: EFECTIVO | E42: REF. | F42: M14573142 | G42: REF. | I42: 1
A44: FECHA | B44: ABONO | C44: FECHA | D44: ABONO | E44: FECHA | F44: ABONO | G44: FECHA | H44: ABONO
A45: 45838 | C45: 45845 | E45: 45852 | G45: 45859 | I45: =B51+D51+F51+H51 -> 720000
A46: 45839 | C46: 45846 | E46: 45853 | G46: 45860
...

Sheet MOVIL 32
A1: RENTAL MOTORS S.A.S Nit. 901843215-2
A5: FOTO | C5: =DATA!B4 -> NOMBRE Y APELLIDO | D5: =DATA!C4 -> CEDULA | E5: =DATA!D4 -> N/CONTACTO
C6: =DATA!B5 -> JULIO CESAR | D6: =PAGOS!C7 -> 5882282 | E6: =DATA!D5 -> 3126889237
C7: =PAGOS!A7 -> JULIO CESAR | D7: MOVIL 32
C9: =PAGOS!A9 -> SALDO ACTUAL PAGADO | D9: =PAGOS!C9 -> DEUDA A PAGAR
C12: =PAGOS!A10 -> 10530000 | D12: =PAGOS!C10 -> 1881500
A13: CUOTAS TOTALES | C13: =PAGOS!H9 -> CUOTA MENSUAL # | D13: CUOTAS RESTANTES
A14: =PAGOS!D5 -> 18 | C14: =PAGOS!H11 -> 14 | D14: =PAGOS!D5-PAGOS!H11 -> 4
A15: CODIGO | B15: MOTO | C15: MODELO | D15: MARCA | E15: PLACA
A16: A2175 | B16: =PAGOS!B2 -> SBR | C16: =PAGOS!C2 -> 2024 | D16: =PAGOS!D2 -> BERA | E16: RLI49H
C17: SOAT | D17: Traspaso de propiedad | E17: PRESTAMO.
C18: ACTIVO | D18: ACTIVO | E18: 0

Sheet DATA
A1: RENTAL MOTORS S.A.S Nit. 901843215-2
A4: MOVIL | B4: NOMBRE Y APELLIDO | C4: CEDULA | D4: N/CONTACTO | E4: CORREO ELECTRONICO | F4: FECHA DE INICIO | G4: DIRECCION | H4: CIUDAD | I4: BARRIO
A5: MOVIL 31 | B5: =PAGOS!A7 -> JULIO CESAR | C5: =PAGOS!C7 -> 5882282 | D5: 3126889237 | F5: 45758
B8: DATOS PERSONALES
B9: NOMBRE Y APELLIDO | C9: PARESTESCO | D9: CEDULA | E9: N/CONTACTO
B13: NOMBRE Y APELLIDO | C13: PARESTESCO | D13: CEDULA | E13: N/CONTACTO
