Workbook

Sheet PAGOS
A1: CODIGO | B1: MOTO | C1: MODELO | D1: MARCA | E1: PLACA | F1: MOVIL | G1: PRECIO | H1: INICIAL
A2: A2175 | B2: BOXER | C2: 2025 | D2: BAJAJ | E2: EXI78H | F2: MOVIL 18 | G2: 6800000 | H2: 800000
A4: COSTO -INICIAL | B4: INTERES | C4: COSTO NETO | D4: MESES | E4: MESUAL | F4: QUINCENAL | G4: SEMANAL | H4: DIARIO
A5: =G2-H2 -> 6000000 | B5: =A5*1.69 -> 10140000 | C5: =A5+B5 -> 16140000 | D5: 24 | E5: =C5/D5 -> 672500 | F5: =E5/2 -> 336250 | G5: =F5/2 -> 168125 | H5: =G5/6 -> 28020.833
A6: NOMBRES | B6: APELLIDO | C6: CEDULA | D6: NACIONALIDAD | E6: NUMERO | F6: SOAT | G6: Traspaso de propiedad | H6: DEUDA DE SEMANA
A7: DAIRO TORRES SALCEDO | C7: 9204960 | D7: COLOMBIANA | F7: 0 | G7: 280000 | H7: 201000
H8: MESES
A9: SALDO ACTUAL PAGADO | C9: DEUDA A PAGAR | E9: DEUDA TOTAL. | G9: DEUDA ADQUIRIDA
A10: =I14+I24+I34+I44+I54+I64+I74+I84+I94+I103+I113+I122+I131+I140+I149+I158+I167+I176+I185+I194+I203+I212 -> 14111000 | C10: =C5-A10 -> 2029000 | E10: =C10+G10+G7 -> 2510000 | G10: =H7 -> 201000 | H10: =I21+I31+I41+I51+I61+I71+I81+I91+I101+I110+I120+I129+I138+I147+I156+I165+I174+I183+I192+I201+I210+I219+I228 -> 21
A12: RENTAL MOTORS S.A.S
A13: FECHA | B13: ABONO | C13: FECHA | D13: ABONO | E13: FECHA | F13: ABONO | G13: FECHA | H13: ABONO
C14: 45558 | E14: 45565 | G14: 45572 | I14: =B20+D20+F20+H20 -> 560000
C15: 45559 | E15: 45566 | G15: 45573
C16: 45560 | D16: 168000 | E16: 45567 | F16: 168000 | G16: 45574 | H16: 168000
C17: 45561 | E17: 45568 | G17: 45575
A18: 45555 | B18: 28000 | C18: 45562 | E18: 45569 | G18: 45576
A19: 45556 | B19: 28000 | C19: 45563 | E19: 45570 | G19: 45577
B20: =SUM(B14:B19) -> 56000 | D20: =SUM(D14:D19) -> 168000 | F20: =SUM(F14:F19) -> 168000 | H20: =SUM(H14:H19) -> 168000 | I20: 1
A21: REF. | C21: REF. | E21: REF. | G21: REF. | I21: 1
A23: FECHA | B23: ABONO | C23: FECHA | D23: ABONO | E23: FECHA | F23: ABONO | G23: FECHA | H23: ABONO
A24: 45579 | B24: 168000 | C24: 45586 | D24: 168000 | E24: 45593 | F24: 168000 | G24: 45600 | H24: 168000 | I24: =B30+D30+F30+H30 -> 672000
A25: 45580 | C25: 45587 | E25: 45594 | G25: 45601
A26: 45581 | C26: 45588 | E26: 45595 | G26: 45602
A27: 45582 | C27: 45589 | E27: 45596 | G27: 45603
A28: 45583 | C28: 45590 | E28: 45597 | G28: 45604
A29: 45584 | C29: 45591 | E29: 45598 | G29: 45605
B30: =SUM(B24:B29) -> 168000 | D30: =SUM(D24:D29) -> 168000 | F30: =SUM(F24:F29) -> 168000 | H30: =SUM(H24:H29) -> 168000 | I30: 2
A31: REF. | C31: REF. | E31: REF. | G31: REF. | I31: 1
A33: FECHA | B33: ABONO | C33: FECHA | D33: ABONO | E33: FECHA | F33: ABONO | G33: FECHA | H33: ABONO
A34: 45607 | B34: 168000 | C34: 45614 | D34: 168000 | E34: 45621 | F34: 168000 | G34: 45628 | H34: 168000 | I34: =B40+D40+F40+H40 -> 672000
A35: 45608 | C35: 45615 | E35: 45622 | G35: 45629
A36: 45609 | C36: 45616 | E36: 45623 | G36: 45630
A37: 45610 | C37: 45617 | E37: 45624 | G37: 45631
A38: 45611 | C38: 45618 | E38: 45625 | G38: 45632
A39: 45612 | C39: 45619 | E39: 45626 | G39: 45633
B40: =SUM(B34:B39) -> 168000 | D40: =SUM(D34:D39) -> 168000 | F40: =SUM(F34:F39) -> 168000 | H40: =SUM(H34:H39) -> 168000 | I40: 3
A41: REF. | C41: REF. | E41: REF. | G41: REF. | I41: 1
A43: FECHA | B43: ABONO | C43: FECHA | D43: ABONO | E43: FECHA | F43: ABONO | G43: FECHA | H43: ABONO
A44: 45635 | B44: 168000 | C44: 45642 | D44: 168000 | E44: 45649 | F44: 168000 | G44: 45656 | H44: 168000 | I44: =B50+D50+F50+H50 -> 672000
A45: 45636 | C45: 45643 | E45: 45650 | G45: 45657
...

Sheet SEMANAL
A1: RENTAL MOTORS S.A.S
A3: SOLO PAGOS POR BANCOLOMBIA | C3: =PAGOS!A7 -> DAIRO TORRES SALCEDO
A4: FECHA DEL PRESTAMOS | B4: =PAGOS!A18 -> 45555
A5: COSTO DEL VEICULO | B5: =PAGOS!G2 -> 6800000 | C5: =PAGOS!F2 -> MOVIL 18
A6: INICIAL DEL VEICULO | B6: =PAGOS!H2 -> 800000
A7: PRESTAMO | B7: =PAGOS!A5 -> 6000000
A8: TASA DE INTERES ( 1,7) | B8: =PAGOS!B5 -> 10140000
A9: COSTO NETO DE LA MOTO | B9: =PAGOS!C5 -> 16140000
A10: SOAT | B10: =PAGOS!F7 -> 0 | C10: =PAGOS!G4 -> SEMANAL
A11: PRESTAMO.
A12: Traspaso de propiedad | B12: =PAGOS!G7 -> 280000
A13: MENSUALIDA GPS | B13: 25000 | C13: =PAGOS!G5 -> 168125
A14: TOTAL APAGAR GPS | B14: =B13*B15 -> 600000
A15: MESES A PAGAR | B15: =PAGOS!D5 -> 24
A16: COSTO NETO DE LA MOTO CON LOS TRAMITES Y SERVICIO | B16: =PAGOS!C5 -> 16140000
A17: SALDO PAGADO | B17: SALDO PENDIENTE | C17: DEUDA ADQUIRIDA | D17: MESES ADQUIRIDO | E17: MESES PAGADO
A18: =PAGOS!A10 -> 14111000 | B18: =PAGOS!E10 -> 2510000 | C18: =PAGOS!G10 -> 201000
