Workbook

Sheet PAGOS
A1: CODIGO | B1: MOTO | C1: MODELO | D1: MARCA | E1: PLACA | F1: MOVIL | G1: PRECIO | H1: INICIAL
A2: A219782G | B2: BOXER | C2: 2026 | D2: BAJA | E2: RMF-89H | F2: 11 | G2: 6800000 | H2: 800000
A4: COSTO -INICIAL | B4: INTERES | C4: COSTO NETO | D4: MESES | E4: MESUAL | F4: QUINCENAL | G4: SEMANAL | H4: DIARIO
A5: =G2-H2 -> 6000000 | B5: =A5*170% -> 10200000 | C5: =A5+B5 -> 16200000 | D5: 18 | E5: =C5/D5 -> 900000 | F5: =E5/2 -> 450000 | G5: =F5/2 -> 225000 | H5: =G5/6 -> 37500
A6: NOMBRES | B6: APELLIDO | C6: CEDULA | D6: NACIONALIDAD | E6: NUMERO | F6: SOAT | G6: Traspaso de propiedad | H6: DEUDA DE SEMANA
A7: YOBANI ANDRES GARZON MARTINEZ | C7: 1002249081 | D7: COLOMBIANO | E7: 3147591450 | F7: 380000 | G7: 280000
H8: MESES
A9: SALDO ACTUAL PAGADO | C9: DEUDA A PAGAR | E9: DEUDA TOTAL. | G9: DEUDA ADQUIRIDA
A10: =I14+I24+I34+I44+I54+I64+I74+I84+I94+I104+I114 -> 9159000 | C10: =C5-A10 -> 7041000 | H10: =I21+I31+I41+I51+I61+I71+I81+I91+I101+I111 -> 10
A12: RENTAL MOTORS S.A.S
A13: FECHA | B13: ABONO | C13: FECHA | D13: ABONO | E13: FECHA | F13: ABONO | G13: FECHA | H13: ABONO
C14: 45901 | E14: 45908 | G14: 45915 | I14: =B20+D20+F20+H20 -> 889000
C15: 45902 | E15: 45909 | G15: 45916
A16: 45896 | B16: 180000 | C16: 45903 | D16: 260000 | E16: 45910 | F16: 224500 | G16: 45917 | H16: 224500
A17: 45897 | C17: 45904 | E17: 45911 | G17: 45918
A18: 45898 | C18: 45905 | E18: 45912 | G18: 45919
A19: 45899 | C19: 45906 | E19: 45913 | G19: 45920
B20: =SUM(B14:B19) -> 180000 | D20: =SUM(D14:D19) -> 260000 | F20: =SUM(F14:F19) -> 224500 | H20: =SUM(H14:H19) -> 224500 | I20: 1
A21: REF. | C21: REF. | E21: REF. | G21: REF. | I21: 1
A23: FECHA | B23: ABONO | C23: FECHA | D23: ABONO | E23: FECHA | F23: ABONO | G23: FECHA | H23: ABONO
A24: 45922 | C24: 45929 | E24: 45936 | G24: 45943 | I24: =B30+D30+F30+H30 -> 898000
A25: 45923 | C25: 45930 | E25: 45937 | G25: 45944
A26: 45924 | B26: 224500 | C26: 45931 | D26: 224500 | E26: 45938 | F26: 224500 | G26: 45945 | H26: 224500
A27: 45925 | C27: 45932 | E27: 45939 | G27: 45946
A28: 45926 | C28: 45933 | E28: 45940 | G28: 45947
A29: 45927 | C29: 45934 | E29: 45941 | G29: 45948
B30: =SUM(B24:B29) -> 224500 | D30: =SUM(D24:D29) -> 224500 | F30: =SUM(F24:F29) -> 224500 | H30: =SUM(H24:H29) -> 224500 | I30: 2
A31: REF. | C31: REF. | E31: REF. | G31: REF. | I31: 1
A33: FECHA | B33: ABONO | C33: FECHA | D33: ABONO | E33: FECHA | F33: ABONO | G33: FECHA | H33: ABONO
A34: 45950 | C34: 45957 | E34: 45964 | G34: 45971 | I34: =B40+D40+F40+H40 -> 897500
A35: 45951 | C35: 45958 | E35: 45965 | G35: 45972
A36: 45952 | B36: 224500 | C36: 45959 | D36: 224500 | E36: 45966 | F36: 224500 | G36: 45973 | H36: 224000
A37: 45953 | C37: 45960 | E37: 45967 | G37: 45974
A38: 45954 | C38: 45961 | E38: 45968 | G38: 45975
A39: 45955 | C39: 45962 | E39: 45969 | G39: 45976
B40: =SUM(B34:B39) -> 224500 | D40: =SUM(D34:D39) -> 224500 | F40: =SUM(F34:F39) -> 224500 | H40: =SUM(H34:H39) -> 224000 | I40: 3
A41: REF. | C41: REF. | E41: REF. | G41: REF. | I41: 1
A43: FECHA | B43: ABONO | C43: FECHA | D43: ABONO | E43: FECHA | F43: ABONO | G43: FECHA | H43: ABONO
A44: 45978 | B44: 224500 | C44: 45985 | D44: 224500 | E44: 45992 | F44: 224500 | G44: 45999 | H44: 224500 | I44: =B50+D50+F50+H50 -> 898000
A45: 45979 | C45: 45986 | E45: 45993 | G45: 46000
...

Sheet SEMANAL
A1: RENTAL MOTORS S.A.S
A3: SOLO PAGOS POR BANCOLOMBIA | C3: =PAGOS!A7 -> YOBANI ANDRES GARZON MARTINEZ
A4: FECHA DEL PRESTAMOS | B4: =PAGOS!A16 -> 45896
A5: COSTO DEL VEICULO | B5: =PAGOS!G2 -> 6800000 | C5: MOVIL 11
A6: INICIAL DEL VEICULO | B6: =PAGOS!H2 -> 800000
A7: PRESTAMO | B7: =PAGOS!A5 -> 6000000
A8: TASA DE INTERES ( 1,7) | B8: =PAGOS!B5 -> 10200000
A9: COSTO NETO DE LA MOTO | B9: =PAGOS!C5 -> 16200000
A10: SOAT | B10: =PAGOS!F7 -> 380000 | C10: =PAGOS!G4 -> SEMANAL
A11: PRESTAMO.
A12: Traspaso de propiedad | B12: =PAGOS!G7 -> 280000
A13: MENSUALIDA GPS | B13: 25000 | C13: =PAGOS!G5 -> 225000
A14: TOTAL APAGAR GPS | B14: =B13*B15 -> 450000
A15: MESES A PAGAR | B15: =PAGOS!D5 -> 18
A16: COSTO NETO DE LA MOTO CON LOS TRAMITES Y SERVICIO | B16: =PAGOS!C5 -> 16200000
A17: SALDO PAGADO | B17: SALDO PENDIENTE | C17: DEUDA ADQUIRIDA | D17: MESES ADQUIRIDO | E17: MESES PAGADO
A18: =PAGOS!A10 -> 9159000 | B18: =PAGOS!C10 -> 7041000
